Workbook

Sheet Instrucciones
A2: INVENTARIO TIPOLOGICO MBTI
A3: (Myers Briggs Type Indicator)
A6: Nombre y Apellidos:
A8: Edad:
A10: Sexo:
A12: Fecha:
A15: Instrucciones
A17: En esta prueba no existen respuestas correctas o incorrectas. Sus respuestas ayudarán a conocer cómo piensa, cómo se siente y cómo se comporta usted generalmente. Conocer sus preferenias puede ayudar a conocer dónde están sus puntos fuertes, el tipo de trabajo en que pudiera tener más exito y cómo agrupar a personas de distintas preferencias para que el equipo sea más util a la sociedad.
A19: Marque con un 1 la alternativa que más le represente. No se entretenga demasiado en cada cuestión; si no pudiera decidirse por una de las alternativas, pase a la siguiente y deje en blanco el espacio correspondiente.

Sheet Parte I
A1: PARTE I: Preguntas 1 - 26
A2: ¿Cuál alternativa se aproxima más a tu forma de sentir o de actuar?
A3: Elige la que mayormente te represente, marcándola con un 1.
A5: 1 | B5: Cuando vas a algún lugar por el día, prefieres… | D5: planear con anticipación que hacer y cuándo | E5: J | F5: =IF(C5=1,E5,0) -> 0
D6: simplemente ir y luego ver que hacer | E6: P | F6: =IF(C6=1,E6,0) -> 0
F7: =IF(C7=1,E7,0) -> 0
A8: 2 | B8: Te consideras a ti mismo como una persona… | D8: más del tipo espontánea | E8: P | F8: =IF(C8=1,E8,0) -> 0
D9: más del tipo organizada | E9: J | F9: =IF(C9=1,E9,0) -> 0
F10: =IF(C10=1,E10,0) -> 0
A11: 3 | B11: Si fueras profesor, preferirías… | D11: realizar clases prácticas | E11: S | F11: =IF(C11=1,E11,0) -> 0
D12: realizar clases teóricas | E12: N | F12: =IF(C12=1,E12,0) -> 0
F13: =IF(C13=1,E13,0) -> 0
A14: 4 | B14: Usualmente eres… | D14: el alma de la fiesta | E14: E | F14: =IF(C14=1,E14,0) -> 0
D15: quieto y reservado | E15: I | F15: =IF(C15=1,E15,0) -> 0
F16: =IF(C16=1,E16,0) -> 0
A17: 5 | B17: Usualmente te llevas mejor con personas | D17: imaginativas | E17: N | F17: =IF(C17=1,E17,0) -> 0
D18: realistas | E18: S | F18: =IF(C18=1,E18,0) -> 0
F19: =IF(C19=1,E19,0) -> 0
A20: 6 | B20: Prefieres… | D20: que tu corazón domine tu cabeza | E20: F | F20: =IF(C20=1,E20,0) -> 0
D21: que tu cabeza domine tu corazón | E21: T | F21: =IF(C21=1,E21,0) -> 0
F22: =IF(C22=1,E22,0) -> 0
A23: 7 | B23: Prefieres hacer las cosas… | D23: dependiendo del impulso del momento | E23: P | F23: =IF(C23=1,E23,0) -> 0
D24: dependiendo de lo planificado | E24: J | F24: =IF(C24=1,E24,0) -> 0
F25: =IF(C25=1,E25,0) -> 0
A26: 8 | B26: Eres… | D26: una persona fácil de conocer por terceros | E26: E | F26: =IF(C26=1,E26,0) -> 0
D27: una persona dificil de conocer por terceros | E27: I | F27: =IF(C27=1,E27,0) -> 0
F28: =IF(C28=1,E28,0) -> 0
A29: 9 | B29: Seguir lo agendado… | D29: te agrada? | E29: J | F29: =IF(C29=1,E29,0) -> 0
D30: te limita? | E30: P | F30: =IF(C30=1,E30,0) -> 0
F31: =IF(C31=1,E31,0) -> 0
A32: 10 | B32: Cuando tienes algo especial que hacer, prefieres… | D32: organizarlo cuidadosamente antes de comenzar | E32: J | F32: =IF(C32=1,E32,0) -> 0
D33: descubrir qué es lo necesario a medida que vas avanzando | E33: P | F33: =IF(C33=1,E33,0) -> 0
F34: =IF(C34=1,E34,0) -> 0
A35: 11 | B35: La mayoría de las veces prefieres… | D35: seguir la corriente | E35: P | F35: =IF(C35=1,E35,0) -> 0
D36: seguir lo agendado | E36: J | F36: =IF(C36=1,E36,0) -> 0
F37: =IF(C37=1,E37,0) -> 0
A38: 12 | B38: La mayoría de las personas dirían que tu eres... | D38: una persona reservada | E38: I | F38: =IF(C38=1,E38,0) -> 0
D39: una persona abierta | E39: E | F39: =IF(C39=1,E39,0) -> 0
F40: =IF(C40=1,E40,0) -> 0
A41: 13 | B41: Prefieres ser considerado,,, | D41: como una persona práctica | E41: S | F41: =IF(C41=1,E41,0) -> 0
...

Sheet Parte II
A1: PARTE II: Preguntas 27 - 58
A2: Cual palabra te representa mejor?. Piensa en el significado de las palabras, no en como se ven o suenan.
A3: Marca con un 1 la que más te representa.
A5: 27 | C5: Cerrado | D5: I | E5: =IF(B5=1,D5,0) -> 0 | F5: 40 | H5: Hechos | K5: 53 | M5: Construir
C6: Abierto | D6: E | E6: =IF(B6=1,D6,0) -> 0 | H6: Conceptos | M6: Inventar
E7: =IF(B7=1,D7,0) -> 0
A8: 28 | C8: Planificado | D8: J | E8: =IF(B8=1,D8,0) -> 0 | F8: 41 | H8: Libre | K8: 54 | M8: Tranquilo
C9: Implanificado | D9: P | E9: =IF(B9=1,D9,0) -> 0 | H9: Planificado | M9: Sociable
E10: =IF(B10=1,D10,0) -> 0
A11: 29 | C11: Abstracto | D11: N | E11: =IF(B11=1,D11,0) -> 0 | F11: 42 | H11: Reservado | K11: 55 | M11: Teorias
C12: Concreto | D12: S | E12: =IF(B12=1,D12,0) -> 0 | H12: Hablador | M12: Hechos
E13: =IF(B13=1,D13,0) -> 0
A14: 30 | C14: Gentil | D14: F | E14: =IF(B14=1,D14,0) -> 0 | F14: 43 | H14: Ordenado | K14: 56 | M14: Compasivo
C15: Firme | D15: T | E15: =IF(B15=1,D15,0) -> 0 | H15: Desordenado | M15: Lógico
E16: =IF(B16=1,D16,0) -> 0
A17: 31 | C17: Pensamiento | D17: T | E17: =IF(B17=1,D17,0) -> 0 | F17: 44 | H17: Ideas | K17: 57 | M17: Analítico
C18: Sentimiento | D18: F | E18: =IF(B18=1,D18,0) -> 0 | H18: Hechos | M18: Sentimental
E19: =IF(B19=1,D19,0) -> 0
A20: 32 | C20: Hechos | D20: S | E20: =IF(B20=1,D20,0) -> 0 | F20: 45 | H20: Compasivo | K20: 58 | M20: Sensible
C21: Ideas | D21: N | E21: =IF(B21=1,D21,0) -> 0 | H21: Previsor | M21: Fascinable
E22: =IF(B22=1,D22,0) -> 0
A23: 33 | C23: Impulsos | D23: P | E23: =IF(B23=1,D23,0) -> 0 | F23: 46 | H23: Beneficios
C24: Decisiones | D24: J | E24: =IF(B24=1,D24,0) -> 0 | H24: Bendiciones
E25: =IF(B25=1,D25,0) -> 0
A26: 34 | C26: Acalorado | D26: E | E26: =IF(B26=1,D26,0) -> 0 | F26: 47 | H26: Sentido Común
C27: Tranquilo | D27: I | E27: =IF(B27=1,D27,0) -> 0 | H27: Teórico
E28: =IF(B28=1,D28,0) -> 0
A29: 35 | C29: Quieto | D29: I | E29: =IF(B29=1,D29,0) -> 0 | F29: 48 | H29: Pocos amigos
C30: Reactivo | D30: E | E30: =IF(B30=1,D30,0) -> 0 | H30: Muchos amigos
E31: =IF(B31=1,D31,0) -> 0
A32: 36 | C32: Sistemático | D32: J | E32: =IF(B32=1,D32,0) -> 0 | F32: 49 | H32: Sistemático
C33: Casual | D33: P | E33: =IF(B33=1,D33,0) -> 0 | H33: Espontáneo
E34: =IF(B34=1,D34,0) -> 0
A35: 37 | C35: Teoria | D35: N | E35: =IF(B35=1,D35,0) -> 0 | F35: 50 | H35: Imaginativo
C36: Certeza | D36: S | E36: =IF(B36=1,D36,0) -> 0 | H36: Concreto
E37: =IF(B37=1,D37,0) -> 0
A38: 38 | C38: Sensitivo | D38: F | E38: =IF(B38=1,D38,0) -> 0 | F38: 51 | H38: Tibio
C39: Justo | D39: T | E39: =IF(B39=1,D39,0) -> 0 | H39: Objetivo
E40: =IF(B40=1,D40,0) -> 0
A41: 39 | C41: Argumentos | D41: T | E41: =IF(B41=1,D41,0) -> 0 | F41: 52 | H41: Objetivo
...

Sheet Parte III
A1: PARTE III: Preguntas 59 - 78
A2: Cuál alternativa se aproxima más a tu forma de sentir o de actuar?
A3: Elige la que mayormente te represente y márcala con un 1
A5: 59 | B5: Cuando comienzas un gran proyecto a desarrollar en una semana | D5: haces un listado de cosas por hacer según orden de importancia | E5: J | F5: =IF(C5=1,E5,0) -> 0
D6: te sumerges en el tema | E6: P | F6: =IF(C6=1,E6,0) -> 0
F7: =IF(C7=1,E7,0) -> 0
A8: 60 | B8: En situaciones sociales encuentras… | D8: dificil comenzar y mantener una conversación con un extraño | E8: I | F8: =IF(C8=1,E8,0) -> 0
D9: fácil hablar largamente con la mayoría de las personas | E9: E | F9: =IF(C9=1,E9,0) -> 0
F10: =IF(C10=1,E10,0) -> 0
A11: 61 | B11: Cuando haces cosas que la mayoría de las personas hace | D11: hacerlo de la manera convencional | E11: S | F11: =IF(C11=1,E11,0) -> 0
B12: prefieres… | D12: inventar tu propio estilo | E12: N | F12: =IF(C12=1,E12,0) -> 0
F13: =IF(C13=1,E13,0) -> 0
A14: 62 | B14: Las personas que recientemente te han conocido pueden decir | D14: rápidamente | E14: E | F14: =IF(C14=1,E14,0) -> 0
B15: que tu eres de determinada manera… | D15: sólo después de que reálmente te conocen | E15: I | F15: =IF(C15=1,E15,0) -> 0
F16: =IF(C16=1,E16,0) -> 0
A17: 63 | B17: Prefieres materias que tratan de… | D17: conceptos y principios | E17: N | F17: =IF(C17=1,E17,0) -> 0
D18: hechos y ejemplos | E18: S | F18: =IF(C18=1,E18,0) -> 0
F19: =IF(C19=1,E19,0) -> 0
A20: 64 | B20: Es un elogio que te llamen | D20: una persona con reales sentimientos | E20: F | F20: =IF(C20=1,E20,0) -> 0
D21: una persona consistente y razonable | E21: T | F21: =IF(C21=1,E21,0) -> 0
F22: =IF(C22=1,E22,0) -> 0
A23: 65 | B23: Encuentras que llevar una agenda es… | D23: necesario a veces, pero la mayoría de las veces no | E23: P | F23: =IF(C23=1,E23,0) -> 0
D24: favorable y útil la mayoría de las veces | E24: J | F24: =IF(C24=1,E24,0) -> 0
F25: =IF(C25=1,E25,0) -> 0
A26: 66 | B26: Cuando estás con un grupo de personas prefieres… | D26: conversar con aquellas personas que conoces bien | E26: I | F26: =IF(C26=1,E26,0) -> 0
D27: disfrutar de la discusión grupal | E27: E | F27: =IF(C27=1,E27,0) -> 0
F28: =IF(C28=1,E28,0) -> 0
A29: 67 | B29: En una fiesta tu… | D29: hablas la mayoría del tiempo | E29: E | F29: =IF(C29=1,E29,0) -> 0
D30: prefieres que otros hablen la mayoría del tiempo | E30: I | F30: =IF(C30=1,E30,0) -> 0
F31: =IF(C31=1,E31,0) -> 0
A32: 68 | B32: La idea de hacer un listado de cosas por hacer el fin de semana… | D32: te motiva | E32: J | F32: =IF(C32=1,E32,0) -> 0
D33: no te llama la atención | E33: P | F33: =IF(C33=1,E33,0) -> 0
F34: =IF(C34=1,E34,0) -> 0
A35: 69 | B35: Es más elogioso ser llamado | D35: competente | E35: T | F35: =IF(C35=1,E35,0) -> 0
D36: compasivo | E36: F | F36: =IF(C36=1,E36,0) -> 0
F37: =IF(C37=1,E37,0) -> 0
A38: 70 | B38: Generalmente prefieres | D38: agendar tus compromisos sociales con cierto espacio de libertad | E38: J | F38: =IF(C38=1,E38,0) -> 0
D39: hacer las cosas según el impulso del momento | E39: P | F39: =IF(C39=1,E39,0) -> 0
F40: =IF(C40=1,E40,0) -> 0
A41: 71 | B41: Cuando trabajas en un gran proyecto | D41: planificas lo que necesitas a medida que vas avanzando | E41: P | F41: =IF(C41=1,E41,0) -> 0
...

Sheet Parte IV
A1: PARTE IV: Preguntas 79 - 93
A2: ¿Cuál palabra te representa mejor?. Piensa en el significado de las palabras, no en como se ven o suenan.
A3: Marca con Un 1 la que más te representa.
A5: 79 | C5: Imaginativo | D5: N | E5: =IF(B5=1,D5,0) -> 0 | F5: 91 | H5: Fiel
C6: Realistico | D6: S | E6: =IF(B6=1,D6,0) -> 0 | H6: Determinado
E7: =IF(B7=1,D7,0) -> 0
A8: 80 | C8: Gran corazón | D8: F | E8: =IF(B8=1,D8,0) -> 0 | F8: 92 | H8: Probado
C9: Mente firme | D9: T | E9: =IF(B9=1,D9,0) -> 0 | H9: Corazonada
E10: =IF(B10=1,D10,0) -> 0
A11: 81 | C11: Mente justa | D11: T | E11: =IF(B11=1,D11,0) -> 0 | F11: 93 | H11: Práctico
C12: Cuidadoso | D12: F | E12: =IF(B12=1,D12,0) -> 0 | H12: Innovador
E13: =IF(B13=1,D13,0) -> 0
A14: 82 | C14: Producción | D14: S | E14: =IF(B14=1,D14,0) -> 0
C15: Diseño | D15: N | E15: =IF(B15=1,D15,0) -> 0
E16: =IF(B16=1,D16,0) -> 0
A17: 83 | C17: Posibilidades | D17: N | E17: =IF(B17=1,D17,0) -> 0
C18: Certezas | D18: S | E18: =IF(B18=1,D18,0) -> 0
E19: =IF(B19=1,D19,0) -> 0
A20: 84 | C20: Ternura | D20: F | E20: =IF(B20=1,D20,0) -> 0
C21: Fuerza | D21: T | E21: =IF(B21=1,D21,0) -> 0
E22: =IF(B22=1,D22,0) -> 0
A23: 85 | C23: Práctico | D23: T | E23: =IF(B23=1,D23,0) -> 0
C24: Sentimental | D24: F | E24: =IF(B24=1,D24,0) -> 0
E25: =IF(B25=1,D25,0) -> 0
A26: 86 | C26: Producir | D26: S | E26: =IF(B26=1,D26,0) -> 0
C27: Crear | D27: N | E27: =IF(B27=1,D27,0) -> 0
E28: =IF(B28=1,D28,0) -> 0
A29: 87 | C29: Novedoso | D29: N | E29: =IF(B29=1,D29,0) -> 0
C30: Conocido | D30: S | E30: =IF(B30=1,D30,0) -> 0
E31: =IF(B31=1,D31,0) -> 0
A32: 88 | C32: Simpatizar | D32: F | E32: =IF(B32=1,D32,0) -> 0
C33: Analizar | D33: T | E33: =IF(B33=1,D33,0) -> 0
E34: =IF(B34=1,D34,0) -> 0
A35: 89 | C35: Firmeza | D35: T | E35: =IF(B35=1,D35,0) -> 0
C36: Ternura | D36: F | E36: =IF(B36=1,D36,0) -> 0
E37: =IF(B37=1,D37,0) -> 0
A38: 90 | C38: Concreto | D38: S | E38: =IF(B38=1,D38,0) -> 0
C39: Abstracto | D39: N | E39: =IF(B39=1,D39,0) -> 0
E40: =IF(B40=1,D40,0) -> 0
D41: F | E41: =IF(G5=1,D41,0) -> 0
...

Sheet Resultados
A1: TUS RESULTADOS:
A3: Tu tipo de personalidad | F3: Tus puntajes
B5: =IF(F19=0,"N/A",(IF(F19>=F18,"I","E"))) -> N/A | C5: =IF(B5="N/A","N/A",IF(B5=A18,IF(F18<14,"Leve",IF(F18<17,"Moderado",IF(F18<20,"Fuerte",IF(F18>=20,"Muy Fuerte",)))),IF(F19<14,"Leve",IF(F19<17,"Moderado",IF(F19<20,"Fuerte",IF(F19>=20,"Muy Fuerte")))))) -> N/A | G5: Extraversion | H5: E | I5: =F18 -> 0 | J5: =F19 -> 0 | K5: I | L5: Introversion
B6: =IF(F21=0,"N/A",IF(F21>=F20,"N","S")) -> N/A | C6: =IF(B6="N/A","N/A",IF(B6=A20,IF(F20<14,"Leve",IF(F20<17,"Moderado",IF(F20<20,"Fuerte",IF(F20>=20,"Muy Fuerte",)))),IF(F21<14,"Leve",IF(F21<17,"Moderado",IF(F21<20,"Fuerte",IF(F21>=20,"Muy Fuerte")))))) -> N/A
B7: =IF(F23=0,"N/A",IF(F23>=F22,"F","T")) -> N/A | C7: =IF(B7="N/A","N/A",IF(B7=A22,IF(F22<14,"Leve",IF(F22<17,"Moderado",IF(F22<20,"Fuerte",IF(F22>=20,"Muy Fuerte",)))),IF(F23<14,"Leve",IF(F23<17,"Moderado",IF(F23<20,"Fuerte",IF(F23>=20,"Muy Fuerte")))))) -> N/A | G7: Sentidos | H7: S | I7: =F20 -> 0 | J7: =F21 -> 0 | K7: N | L7: Intuición
B8: =IF(F25=0,"N/A",IF(F25>=F24,"P","J")) -> N/A | C8: =IF(B8="N/A","N/A",IF(B8=A24,IF(F24<14,"Leve",IF(F24<17,"Moderado",IF(F24<20,"Fuerte",IF(F24>=20,"Muy Fuerte",)))),IF(F25<14,"Leve",IF(F25<17,"Moderado",IF(F25<20,"Fuerte",IF(F25>=20,"Muy Fuerte")))))) -> N/A
G9: Pensamiento | H9: T | I9: =F22 -> 0 | J9: =F23 -> 0 | K9: F | L9: Sentimiento
G11: Juicio | H11: J | I11: =F24 -> 0 | J11: =F25 -> 0 | K11: P | L11: Percepciones
A16: Total Raw Points
B17: Part I | C17: Part II | D17: Part III | E17: Part IV | F17: Total
A18: E | B18: =COUNTIF('Parte I'!$F$5:$F$81,A18) -> 0 | C18: =COUNTIF('Parte II'!$E$5:$E$99,Resultados!A18) -> 0 | D18: =COUNTIF('Parte III'!$F$5:$F$63,Resultados!A18) -> 0 | E18: =COUNTIF('Parte IV'!$E$5:$E$48,Resultados!A18) -> 0 | F18: =SUM(B18:E18) -> 0
A19: I | B19: =COUNTIF('Parte I'!$F$5:$F$81,A19) -> 0 | C19: =COUNTIF('Parte II'!$E$5:$E$99,Resultados!A19) -> 0 | D19: =COUNTIF('Parte III'!$F$5:$F$63,Resultados!A19) -> 0 | E19: =COUNTIF('Parte IV'!$E$5:$E$48,Resultados!A19) -> 0 | F19: =SUM(B19:E19) -> 0
A20: S | B20: =COUNTIF('Parte I'!$F$5:$F$81,A20) -> 0 | C20: =COUNTIF('Parte II'!$E$5:$E$99,Resultados!A20) -> 0 | D20: =COUNTIF('Parte III'!$F$5:$F$63,Resultados!A20) -> 0 | E20: =COUNTIF('Parte IV'!$E$5:$E$48,Resultados!A20) -> 0 | F20: =SUM(B20:E20) -> 0
A21: N | B21: =COUNTIF('Parte I'!$F$5:$F$81,A21) -> 0 | C21: =COUNTIF('Parte II'!$E$5:$E$99,Resultados!A21) -> 0 | D21: =COUNTIF('Parte III'!$F$5:$F$63,Resultados!A21) -> 0 | E21: =COUNTIF('Parte IV'!$E$5:$E$48,Resultados!A21) -> 0 | F21: =SUM(B21:E21) -> 0
A22: T | B22: =COUNTIF('Parte I'!$F$5:$F$81,A22) -> 0 | C22: =COUNTIF('Parte II'!$E$5:$E$99,Resultados!A22) -> 0 | D22: =COUNTIF('Parte III'!$F$5:$F$63,Resultados!A22) -> 0 | E22: =COUNTIF('Parte IV'!$E$5:$E$48,Resultados!A22) -> 0 | F22: =SUM(B22:E22) -> 0
A23: F | B23: =COUNTIF('Parte I'!$F$5:$F$81,A23) -> 0 | C23: =COUNTIF('Parte II'!$E$5:$E$99,Resultados!A23) -> 0 | D23: =COUNTIF('Parte III'!$F$5:$F$63,Resultados!A23) -> 0 | E23: =COUNTIF('Parte IV'!$E$5:$E$48,Resultados!A23) -> 0 | F23: =SUM(B23:E23) -> 0
A24: J | B24: =COUNTIF('Parte I'!$F$5:$F$81,A24) -> 0 | C24: =COUNTIF('Parte II'!$E$5:$E$99,Resultados!A24) -> 0 | D24: =COUNTIF('Parte III'!$F$5:$F$63,Resultados!A24) -> 0 | E24: =COUNTIF('Parte IV'!$E$5:$E$48,Resultados!A24) -> 0 | F24: =SUM(B24:E24) -> 0
A25: P | B25: =COUNTIF('Parte I'!$F$5:$F$81,A25) -> 0 | C25: =COUNTIF('Parte II'!$E$5:$E$99,Resultados!A25) -> 0 | D25: =COUNTIF('Parte III'!$F$5:$F$63,Resultados!A25) -> 0 | E25: =COUNTIF('Parte IV'!$E$5:$E$48,Resultados!A25) -> 0 | F25: =SUM(B25:E25) -> 0

Sheet ISTJ
A1: Los ISTJ se caracterizan por su decisión en asuntos prácticos. Son los guardias de las instituciones tradicionales. Un adjetivo que los describe justamente es digno de confianza. Representan cerca del 6% de la población general. Cuando dan su palabra, siempre la cumplirán. Se muestran muy inquietos con la idea de una nación, estado, institución o familia en peligro de bancarrota.
A3: Esté en casa o en el trabajo, el ISTJ es más bien callado y serio. Los ISTJ son muy perseverantes y fidedignos. La idea de no ratificar un contrato los horroriza. Cuando dan su palabra, empeñan su honor. Se puede contar con ellos para conservar los recursos de la institución a la que ellos pertenecen y para aportar su punto pragmático de vista. Atienden a sus deberes sin gran pompa ni platillos; por lo tanto, la dedicación que aportan a su trabajo puede pasar desapercibida o no apreciada.
A5: El interés de los ISTJ en poner atención a cada detalle a la justicia, a los procedimientos prácticos, al fluido armonioso de personal y de materiales inclina a este tipo a ocupaciones donde dichas preferencias son útiles. Por ejemplo, los ISTJ son excelentes inspectores de Banca y de Hacienda, auditores o contables. También pueden interesarles las inversiones bursátiles, especialmente aquellas acciones de compañías preferidas. No se arriesgarán con su propio dinero o con el de otros.
A7: Los ISTJ saben operar con cifras difíciles y detalladas. Transmiten un mensaje de formalidad y estabilidad, lo cual los hace excelentes supervisores de, por ejemplo, una sección de un hospital, de una biblioteca, o de operaciones mercantiles. Tienen la capacidad de trabajar en pompas fúnebres, de ayudante o investigador legal. Maestros de escuelas superiores que se dedican a enseñar estudios mercantiles, economía doméstica, educación física y ciencias físicas serán ISTJ. También lo serán altos oficiales del Cuerpo Femenino del Ejército (Women's Army Corps). A menudo este tipo parece tener hielo en las venas porque la gente no sabe ver en un ISTJ su vulnerabilidad a la crítica.
A9: Los ISTJ tienen paciencia con su trabajo y con los procedimientos que rigen una institución, aunque no tanta con las metas individuales de la gente que trabaja en dicha institución. Los ISTJ procurarán que las materias primas se entreguen cuándo y dónde corresponda hacerlo; el material estará en su lugar apropiado a la hora debida. Y los ISTJ preferirían que así fuera el caso también con las personas.
A11: Carreras Asociadas
A12: Ejecutivos de negocios, administradores y gerentes
A13: Oficinistas contables y financieros
A14: Policias y detectives
A15: Jueces
A16: Abogados
A17: Doctores y dentistas
... A21: Se lleva mejor con ESFP y ESTJ

Sheet ISTP
A1: Al ser tan impulsivo como cualquier otro SP, la vida de un ISTP es arte en movimiento -- y para él, la accion resulta ser un fin en sí. La acción para el ISTP será más satisfactoria si procede de un impulso más que de un propósito. Si la acción está al servicio de un fin o dirección, que ésta se las vea por si sola; porque no permitirá que influya la ejecución. El acto es autodirigido, autopropulsado, que contiene sus propios imperativos que no se doblegará a meras reglas, reglamentos o leyes. Los ISTP consideran a todos iguales y serán extremadamente leales a sus "camaradas," pero también serán altamente insubordinados, considerando jerarquías y autoridad como algo innecesario e incluso superfluo. No quiere ello decir que vayan contra las reglas; simplemente las ignoran. El ISTP debe de hacer lo que le parece; sentirse libre para variar según le parezca. Y los ISTP se sienten orgullosos, o quieren sentirse, de su habilidad para variar con destreza.
A3: Los ISTP no temen nada. Se arriesgan más que otros tipos a pesar de que (y a menudo frecuentemente) se lastiman. De todos los tipos, los ISTP se oponen -- u oponen su técnica -- a la casualidad, a las probabilidades, al destino. Les encanta sentirse excitados; buscan excitación todos los días, en la forma de movimiento rápido -- carreras, paracaídismo o surfing, por ejemplo. Esta sed de acción los condiciona a sentirse más aburridos que otros tipos; su necesidad los lleva a buscar una rápida acción. Lo raro, sin embargo, es que no se aburren cuando hacen lo que les gusta, aunque se pasen largos ratos sin hacer nada, como es cuando viajan, cazan, pescan o hacen surf.
A5: La personalidad del ISTP se puede observar con mayor facilidad cuando tratan de dominar el uso de cualquier artefacto mecánico, ya sea éste un taladro microscópico o un jet supersónico. De pequeños se sienten atraídos como imanes a dichas máquinas; deben usarlas, manipularlas, y caen en sus manos pidiendo ser usadas. Muchos pilotos sabían a la edad de cinco años que iban a serlo. Los ISTP tienden a trabajar en actividades que les permite usar herramientas: conduciendo, guiando, moviendo. Si observamos cualquier instrumento o máquina -- sea un bisturí o una enorme excavadora -- utilizado con increíble destreza, las manos que lo mueven, por seguro, serán las de un ISTP. Otros usan herramientas, pero no con la habilidad de un ISTP. Sin duda, deberíamos calificar a los ISTP como los artesanos instrumentales ya que ninguno como ellos domina el uso de los instrumentos de trabajo y los supedita a la fuerza de sus impulsos. Por supuesto, los ISTP -- personificados en Miguel Angel y en Michelangelo -- trabajan (o mejor dicho aún, juegan) con sus herramientas siguiendo sus impulsos personales y no las demandas de un horario. Si el horario impuesto exteriormente coincide con el impulso, bien; si no, de poco servirá el horario.
A7: Si hay un instrumento que atrae al ISTP es un arma. Si el ISTP se enfrenta a la sociedad (por la razón que sea), utilizará sus armas con talento mortífero. El asesino pagado de hoy día, el pistolero del Oeste americano y el duelista de la Europa del siglo XVIII son ejemplos de esta precisión homicida. El asesino, el pistolero y el duelista por igual se vanagloriaban de su increíble destreza. Por suerte, se enfrentan a otros con idéntica habilidad, los buenos guerreros de la tierra: el soldado, el marshal, el policía, el agente secreto. Esto no quiere decir que todos los guerreros, buenos o malos, son ISTP, o que los ISTP son expertos en armas; más bien que el virtuoso en armas es más frecuentemente que no un ISTP.

Sheet ISFJ
A1: Seis de cada cien personas son ISFJ. Su deseo primario es servir y atender las necesidades individuales de las personas. Los ISFJ acarrean un sentido de la historia, un sentido de continuidad con los acontecimientos y relaciones del pasado. Valoran altamente las tradiciones y la conservación de los recursos. El último hedonista de todos los tipos, los ISFJ creen que el trabajo es bueno; el ocio se debe ganar. Los ISFJ trabajan muchas, muchas horas. Cuando empiezan una labor, la terminarán haciendo todo lo humanamente posible. Valoran y respetan los modos tradicionales de hacer las cosas y de hacerlas bien. Nunca ponen en duda la eficiencia y efectividad de un procedimiento establecido. Los procedimientos dictados por un manual son ley. Si otros violan o ignoran estos procedimientos de operación tradicionales, los ISFJ se molestan e irritan, aunque no expresen claramente dichas reacciones. Por regla general, dicha irritación se mantiene internamente y les produce fatiga y tensión muscular.
A3: Los ISFJ son muy dignos de confianza y rara vez se sentirán satisfechos en situaciones de trabajo donde las reglas cambian constantemente. Su necesidad primaria de servir a otros los dirige a ocupaciones tales como el cuidado de enfermos, la enseñanza, trabajos de secretaría, la práctica médica (especialmente medicina general), trabajos de biblioteca, la administración de empresas a nivel medio. Se relacionan bien con personas que los necesitan; por ejemplo, enfermos, analfabetos, estudiantes y el "jefe." Se sienten muy satisfechos cuando se cuidan de las necesidades de otros y rinden sus servicios con gentileza y eficacia. Cuando la otra persona no los necesita más, la relación puede que cambie de índole al desinteresarse el ISFJ. Disfrutan ayudando al oprimido y sabe mejor que ningún otro tipo ayudar a la gente. Si una situación requiere dicha conducta por su parte, lo harán con el "debido respeto." Los ISFJ tienen un extraordinario sentido de la responsabilidad y un talento fuera de lo corriente para ejercer rutinas que requieren procedimientos repetitivos y continuos; por ejemplo, los ISFJ pueden ser extraordinarios secretarios, enfermeros altamente eficientes y maestros dedicados. La especulación y la teoría no intrigan a los ISFJ, quienes dejan los asuntos menos prácticos para otros y se mantienen ellos mismos más pragmáticos y aferrados a la tierra.
A5: Los ISFJ tienden a ser devotos y leales a su jefe e identificarse personalmente más que por medio de la institución. Esperan que otros, incluyendo a su jefe, sigan los procedimientos y se disgustan cuando la gente no se comporta como debería. Los ISFJ a menudo parecen sentirse personalmente responsables de que el personal de una institución o negocio siga las reglas y rutinas establecidas. A menudo tienen muy presente el nivel social que proporcionan los títulos, el ambiente, los puestos de importancia, y saben aprovecharse de esta circunstancia. Tienen muy presente también el valor de los recursos materiales y aborrecen el desaprovechamiento o abuso de estos recursos. Ahorrar, guardar para un futuro imprevisto, prepararse para emergenciasÑestas son acciones importantes.
A7: Los ISFJ puede que experimenten cierta incomodidad cuando los ponen en un puesto de autoridad sobre otros y tenderán a hacerlo todo ellos mismos más que insistir que otros hagan su trabajo propio. Como resultado, los ISFJ están con frecuencia sobrecargados de trabajo.

Sheet ISFP
A1: Aunque todos los SP son artesanos por naturaleza, no practican su habilidad con la misma devoción a la gracia y al adorno que el ISFP. Por alguna razón u otra, el ISFP parece más inclinado a las "bellas artes" que los otros SP; así cuando un director, pintor o bailarín especialmente dotado aparece, él o ella, más frecuentemente que no, posee la personalidad del ISFP. Beethoven, Toscanini, Rembrant y Nijinski, como muestra la investigación tipohistórica, fueron claramente ISFP. Pero el temperamento ISFP es muy difícil de observar, incluso en los grandes artistas, y por eso el ISFP es problamente el más incomprendido de todos lo tipos.
A3: Una circunstancia importante para dicho mal entendimiento es la tendencia que tienen los ISFP a no expresarse directamente, sino por medio de la acción. Si encuentran un medio de expresión, algún tipo de arte, entonces expresan su personalidad a través de dicho medio. Si no, no aparece y nadie los conoce, pasando la personalidad totalmente inadvertida. Por supuesto, en aquellos raros casos en que logran una expresión importante, como son los virtuosos, los ISFP se convierten en celebridades, pero su naturaleza queda muy lejos de ser visible. Harpo Marx, un extraordinario actor cómico, puede ser considerado como un prototipo, en su simultánea celebridad e invisibilidad muda.
A5: Cuando se les observa detenidamente, estos relativamente infrecuentes SP (5 por ciento de la población son ISFP, comparados con 15 por ciento de ESFP) son tan hedonistas e impulsivos como los otros SP. No tenemos aquí la búsqueda de significado del NF, ni la fascinación por la ciencia (NT) o el comercio (SJ). Los ISFP viven vidas epicúreas en el aquí y ahora, y con el mayor donaire posible. No planean ni se preparan. Sumersión en su arte no es preparación para algo que harán más tarde; más bien lo experimentan intensamente, en ese momento. Los ISFP no esperan, porque esperar es ver cómo el impulso se marchita y muere; quieren y valoran sus impulsos y los ven como el centro de su vida. Ni tampoco los ISFP se dedican a ensayar para mejorar su arte; más bien se sienten atrapados por un imán o torbellino. Así las largas horas de "ensayo" que el virtuoso "da" a su arte no es ensayo y no las da; la acción en sí lo hace y se lo quita del (complaciente) virtuoso. El acto es el dueño del ISFP, no al revés; por lo tanto debemos abandonar la idea de que los ISFP ponen extremo cuidado y planifican con gran atención sus ensayos. Pintan, cantan, hacen piruetas, bailan, corren, patinan, simplemente porque tienen que hacerlo: suben la montaña porque está ahí.
A7: Como el ISFP siempre se siente aferrado por cualquier acción que experimenta en el momento indicado, más que ensaya con miras puestas en la distancia, no hay duda que notará fatiga, daño o peligro. A menudo no prestan atención a estas circunstancias que acompañan muchas de sus actividades. No es que no las tengan presentes; lo que pasa es que se sumergen de tal forma en su actividad que simplemente pasan inadvertidas. En esto el ISFP es similar a otros SP y diferente atodos los demás tipos.
A9: Los ISFP, como otros SP, tienen una clase especial de inteligencia. Recuerda, por favor, que la inteligencia se define en este libro como la habilidad de hacer bien las cosas bajo circunstancias distintas. Esta categoría particular de inteligencia podría llamarse "concentración artesana." Este talento se diferencia radicalmente del que poseen los NF, los NT y los SJ (dado por sabido, por supuesto, que ellos también tienen sus propias habilidades únicas e innatas). Esta concentración artesana, de una forma u otra mantiene a los ISFP más en contacto con la realidad. Mientras que el ISTP está más sintonizado con el instrumento, por decirlo así, el ISFP se sintoniza con el color, las líneas, el material, las tonalidades el tacto, el movimiento, la vista y el oído en armonía. Los sentidos del ISFP parecen estar más finamente sintonizados que los de otros. Rembrant parecía casi probar los colores, tan fina era su discriminación. Toscanini sabía distinguir una nota falsa dentro de la más compleja partitura instrumental de orquesta. Y las palabras de Hemingway degustaban y olían y tocaban las olas. Esta referencia extrema a lo concreto y específico parece salirle naturalmente al ISFP y la tiene metida "en la médula de su constitución."

Sheet INFJ
A1: Los INFJ se concentran en las posibilidades, piensan en términos de principios y llegan con facilidad a determinar sus conclusiones. El pequeño porcentaje de este tipo (1%) es lamentable porque dicho grupo manifiesta una gran energía para fomentar el bienestar de otros y disfrutan cuando se les da la oportunidad de ayudar al prójimo. Estas personas se caracterizan por una profunda personalidad; son en sí mismas complejas y saben entender y tratar a la vez a gente complicada o asuntos de difícil resolución.
A3: Es muy posible que el INFJ tenga visiones de acontecimientos humanos ocurridos en el pasado, venideros o presentes. Si una persona muestra habilidad para entender fenómenos síquicos, es casi seguro que será un INFJ. Los INFJ son capaces de apreciar o Òsentir,Ó en muchos casos, las emociones de otros, incluso antes de que estos últimos se den cuenta de las mismas. Los INFJ llegan a intuir la bondad y la maldad que se desprenden de otros, aunque no sepan cómo llegaron a apreciar dichos aspectos. Sin embargo, cualquier acontecimiento posterior a esa ÒsensaciónÓ parece corroborar la impresión que ha experimentado el INFJ.
A5: Por lo general, los INFJ son buenos estudiantes y logran su propósito académico con una creatividad sin pretensiones. A la vez tienden a ser perfeccionistas que se dedican con excesivo celo a un trabajo que no requiere mayor atención o esfuerzo. No son líderes natos, aunque sí influyen en gran modo entre bastidores.
A7: Resulta muy difícil conocer bien a un INFJ. Su vida íntima es muy rica y activa. Y sólo la comparten con aquellas personas a quienes tratan con frecuencia y les tienen gran confianza. De lo contrario, se cierran en sí mismos. Por su natural tendencia a la introyección, se les puede herir fácilmente al ser mucho más vulnerables que cualquier otro grupo. A veces incluso sorprenden a aquellas personas que creen conocerlos bien ya que, de pronto, en momentos inesperados, se comportan de un modo que sorprende hasta a los más allegados. Y no es que los INFJ sean contradictorios; ni mucho menos, su conducta es consistente y valoran su integridad. Lo que ocurre es que su personalidad resulta compleja y complicada a tal punto que llega a sorprenderles incluso a ellos mismos.
A9: Los INFJ tratan de complacer a otros, para lo cual se esfuerzan en aportar su mejor estado de ánimo sea cual sea la situación. Prefieren estar de acuerdo con las opiniones de otras personas ya que consideran cualquier conflicto como algo desagradable y destructivo. Un INFJ experimenta percepciones extrasensoriales más que ningún otro tipo aunque es verdad que todos son capaces de apreciar dicho fenómeno. Los INFJ experimentan vívidas imágenes que se manifiestan tanto en la memoria como en la intuición, lo cual le da un aspecto genial que otros aprecian como ciertas manifestaciones místicas. Gracias a dicha imaginación los INFJ componen excepcionales y complejas obras de arte en la música, en sistemas matemáticos, en poemas, en dramas, en novelas. De hecho, los INFJ son los tipos más poéticos. Así como un ENTJ no sabe no dirigir, los INFJ deben de intuir. Esta característica se proyecta a la gente, a los objetos, a los acontecimientos, formulando visiones, presagios, imágenes visuales y auditivas de hechos por acontecer. Los INFJ son capaces de comunicarse con personas ausentes.

Sheet INFP
A1: Los INFP presentan un aspecto tranquilo y agradable al mundo y parecen reservados e incluso tímidos. Aunque muestran una actitud poco comunicativa a otros, por dentro son todo lo contrario. Tienen una capacidad de cariño que no se encuentra en otros tipos. Quieren profundamente -- de hecho, apasionada­menta -- a unas pocas personas especiales o se dedican con tesón a una causa. Una palabra que capta a este tipo es idealista. A veces, esta característica los hace sentirse aislados, sobre todo teniendo en cuenta que se encuentra sólo un 1% entre la población general.
A3: Los INFP tienen un profundo sentido del honor que se deriva de sus principios internos. El INFP es el Príncipe o la Princesa de la mitología, el Campeón del Rey, el Defensor de la Fé y el Guardián del castillo. Sir Galahad y Juana de Arco son los prototipos de un INFP. Para entender a los INFP hay que entender su causa puesto que son capaces de grandes sacrificios por alguien o algo.
A5: Los INFP buscan unidad en su vida, unidad de cuerpo y mente, emociones e intelecto. A menudo tienen un trágico motivo sutil presente en sus vidas que otros no saben detectar. Su profunda dedicación a lo positivo y a las buenas causas hace que los INFP siempre estén alertas a lo negativo y al mal, lo cual puede formularse como una fascinación hacia lo profano. Así los INFP pueden vivir en una paradoja, atraídos por la pureza y la unidad, pero mirando sobre el hombro hacia lo sucio y lo profano. Cuando los INFP creen que han cedido a una tentación impura, se impondrán sacrificos como expiación. La reparación, sin embargo, ocurre dentro del INFP, quien no se siente motivado a hacerla pública.
A7: Los INFP prefieren el proceso basado en principios que el puramente lógico. Responden a lo bello sobre lo feo, lo bueno sobre lo malo y lo moral sobre lo inmoral. Ganan sus impresiones de un modo fluido, global y difuso. Les salen las metáforas y símiles naturalmente pero algo forzadas. Los INFP tienen un don para interpretar símbolos, al igual que para crearlos, y por eso escriben de un modo lírico. Muestran una tendencia a tomarse libertades deliberadas con la lógica. Al contrario de un NT, se toman la lógica como algo optativo. Los INFP, a veces asumirán una familiaridad innecesaria en un área puesto que su actitud impresionista y global de tratar a la realidad les impide registrar suficiente número de detalles como para conocerla a fondo. Los INFP tendrán dificultad pensando en términos de una estructura condicional; ven las cosas o reales o imaginarias y les impacientan las hipótesis.
A9: Los INFP se adaptan bien en el trabajo y aceptan nuevas ideas e información, tiene muy presentes a la gente y sus sentimientos y se relacionan bien con la mayoría, aunque lo hagan un poco distantes. A los INFP no les gustan las interrupciones telefónicas y trabajan bien solos o con otros. Tienen paciencia con las situaciones complicadas, pero poca con los detalles rutinarios. Se equivocarán en cuanto a un hecho, pero rara vez con un principio. Se inclinan hacia el apostolado, la labor misionera, la enseñanza universitaria, la siquiatría, la arquitectura, la sicologíaÑpero ignoran el mundo de los negocios. Se dedican con entusiasmo para alcanzar el fondo académico necesario que les proporcione una carrera y a menudo sacan mejores notas en la universidad que en la escuela superior. Tienen un interés natural en las actividades académicas y demuestran, como los otros NF, una facilidad extraordinaria para los idiomas. A menudo ÒoyenÓ una llamada que les pide que ayuden a los que lo necesitan. Y hacen los sacrificios necesarios para responder a esa llamada, incluso si ello significa pedir que otros hagan lo mismo. Los INFP pueden llegar a ser excelentes novelistas y actores que hacen el papel de una persona de gran carácter o personalidad, puesto que, mejor que ningún otro tipo, saben abandonar su propia personalidad en la representación del papel que deben de actuar.

Sheet INTJ
A1: Los INTJ son, de todos los tipos, los que mayor confianza tienen en sí mismos. Se dan buena cuenta de las facultades que poseen. Constituyen el 1% de la población total y viven en una realidad introspectiva que se enfoca en las posibilidades usando el proceso intelectual en la forma de lógica empírica. Prefieren que los eventos y las personas sirvan algún uso positivo. Las decisiones le llegan naturalmente a los INTJ. Una vez hechas, los INTJ quedan tranquilos. Los INTJ se proyectan hacia el futuro más que al pasado, y la palabra que mejor captura el espíritu de los INTJ es constructor -- un constructor de sistemas y aplicador de modelos teóricos.
A3: La autoridad basada en puesto, rango, título o determinada en algún libro no tiene fuerza en absoluto para los INTJ. Este tipo no sucumbe a la magia de frases de propaganda, de precaución o de distinción. Si una idea o postura tienen sentido, el INTJ la adoptará; si no, no lo hará, no importa quien la haya propuesto. Como en el caso del INTP, la autoridad por sí no impresiona al INTJ.
A5: Sin embargo, los INTJ se conformarán con las reglas si son útiles, no porque crean en ellas o tengan sentido, sino por su única visión de la realidad. Son los supremos pragmáticos que ven la realidad como algo arbitrario y creado. Por lo tanto se la puede usar como una herramient -- o ignorarla. La realidad es bastante maleable y se puede cambiar, conquistar o dominar. La realidad es crucial para el refinamiento de las ideas, y en este sentido, los INTJ son los más teóricos de todos los tipos. Donde el ESTP ve las ideas como un peón de la realidad, un INTJ ve la realidad como un peón de las ideas: ninguna idea es lo bastante alocada como para no ser considerada. Los INTJ experimentan constantes accesos de actividad intelectual y están siempre abiertos a nuevos conceptos y a analizarlos agresivamente.
A7: Los INTJ manipulan el mundo de la teoría como si fuera un enorme tablero de ajedrez, siempre buscando estrategias y tácticas que tengan resultados. En su tendencia hacia la lógica, los INTJ se parecen a los INTP. Sin embargo, la lógica de un INTJ no se limita a lo que pueda expresar lógicamente. Contrarios a los INTP, los INTJ necesitan tener sólo una impresión vaga, intuitiva de la lógica no expresada de un sistema para continuar seguros en su camino. Las cosas necesitan sólo parecer lógicas; esto es bastante. Más aún, tienen un ojo aguzado para ver las consecuencias que la aplicación de nuevas ideas o posturas puedan tener. Pueden ser bastante crueles cuando establecen sistemas, sin importarles despedir personal para ahorrar tiempo y energía. Los INTJ abandonan pronto teorías que no pueden aplicarse.
A9: Deberíamos observar el modo en que los INTJ tratan a la realidad más que su manera de tratar a las ideas para apreciar cómo son ellos. Su pensamiento consciente es extrovertido y empírico. Así, saben generalizar, clasificar, sumarizar, recoger evidencia, probar y demostrar mejor que los INTP. Los INTJ se sienten menos cómodos con la razón pura, esto es, el sistema lógico, en el que los principios son explícitos. En este sentido se parecen a los ENTJ. Los INTJ usan su intuición para entender la coherencia más que la lógica deductiva. Los INTJ tienden a completar las cosas, siempre con un ojo puesto en las consecuencias a largo plazo. Las ideas tienen su propia fuerza para los INTJ, aunque someten cada idea a una prueba de utilidad. Les estimulan las dificultades y responden a cualquier desafío que requiera creatividad. Este aspecto de su personalidad inclina a los INTJ a dedicarse a ocupaciones en las que los modelos teóricos se pueden transformar en realidad. Desarrollan sistemas de datos y de personal donde trabajan si se les da la más ligera oportunidad. Se destacan en el campo de investigaciones científicas y en el ejecutivo donde generan una plétora de implantación de ideas. Si se le pone a trabajar con un INTP, quien es el arquitecto de sistemas, el INTJ proporciona una dimensión a una organizatión que asegura que el trabajo del INTP no se llenará de polvo en alguna estantería.

Sheet INTP
A1: Los INTP manifiestan la mayor precisión de pensamiento y vocabulario de todos los tipos; se dan cuenta en seguida de las distinciones e inconsistencias de pensamiento y lenguaje. La palabra que mejor capta el estilo único del INTP es arquitecto el arquitecto de ideas y de sistemas al igual que el arquitecto de edificios. Este tipo se encuentra sólo en 1% de la población y, por lo tanto, no con la frecuencia de otros tipos.
A3: Los INTP detectan contradicciones en las declaraciones aunque haga tiempo que se hayan expresado. La exploración intelectual de los INTP tiene una cualidad principal; esto es, los INTP buscan lo que es importante y pertinente al asunto que se trata. Como consecuencia, los INTP saben concentrarse mejor que ningún otro tipo.
A5: La autoridad que se desprendería de un puesto, rango o reconocimiento general no impresiona a los INTP. Consideran sólo el peso que traen las declaraciones lógicas y coherentes. La autoridad externa por sí misma no viene al caso. A los INTP les ponen muy nerviosos la redundancia y la incoherencia. Como tiene un deseo de entender el universo, un INTP busca constantemente leyes naturales. La curiosidad relacionada a estas claves del universo es una fuerza de empuje para este tipo.
A7: Los INTP valoran la inteligencia que poseen y la que tienen otros, pero pueden convertirse en aficionados intelectuales a resultas de su necesidad de adquirir ideas, principios o de entender la conducta humana. Y cuando aprenden algo, lo retienen. Los INTP se pueden obsesionar con el análisis. Una vez que se concentran en un proceso intelectual, dicho proceso toma una voluntad propia y no paran hasta que entienden toda la complejidad de una idea o de un tema. Pueden convertirse en unos pretensiosos intelectuales y mostrar poca paciencia con aquellos que no tienen tanta inteligencia. Esta cualidad genera hostilidad y conducta defensiva por parte de otros, quienes describen a los INTP como arrogantes.
A9: Para los INTP, el mundo existe primordialmente para ser entendido. La realidad es trivial, un lugar para probar ideas. Es esencial que se entienda el universo y que lo que se diga del universo se diga correctamente, con coherencia y sin redundancia. Esto es el propósito básico para un INTP. No importa si otros no entienden o no aceptan sus ideas.

Sheet ESTP
A1: Los ESTP son hombres y mujeres de acción. Cuando alguien que tenga esta personalidad se encuentre presente en un sitio, las cosas empiezan a pasar: se encienden las luces, toca la música, empieza la representación. Y una representación resulta para el ESTP, el emprendedor extraordinario, el diplomático internacional, el conciliador y el negociador por excelencia. Aproximadamente 13 por ciento de la población general son de este tipo extrovertido, sensorial, intelectual y perceptivo. Si se usara un solo adjetivo para describir a los ESTP, ingenioso sería el más adecuado.
A3: La vida nunca parece aburrida cuando se está al lado de un ESTP. Su estilo atractivo y amistoso tiene un tono dramático que tranforma el evento más rutinario y mundano en algo excitante. Los ESTP saben dónde están los mejores restaurantes y el jefe de camareros sabrá cómo se llama. Los ESTP tienen una capacidad extraordinaria para desenvolverse en el mundo de las activiades sociales; son afables y corteses. Pocos como él saben utilizar el mundo exterior para su beneficio.
A5: Los ESTP tienen un don especial para observar lo que motiva a las personas; son hipersensibles a las mínimas indicaciones no verbales de la gente, cosa que pasaría inadvertida para muchos otros tipos. Son genios para usar estas observaciones y "vender" al "cliente." La vista del ESTP está puesta en los ojos del que mira, y todas sus acciones se dirigen al auditorio. Ingeniosos, inteligentes y divertidos, los ESTP parecen tener una cantidad poco corriente de empatía, cuando en realidad no es este el caso; más bien, están tan al tanto de las mínimas señales que proyectan los otros que se anticipan a cualquier movimiento de postura que estos puedan hacer. Los ESTP saben usar la información que adquieren para lograr los fines que se proponen -- aparentemente se arriesgan con nervios de acero a lo que otros considerarían un esfuerzo suicida. Otros tipos encuentran esta actitud como algo agotador, pero a los ESTP les excita trabajar al borde del precipicio. Los ESTP son unos pragmáticos que no ponen ningún impedimento para lograr el fin que se proponen: los medios justifican el fin -- lamentable, pero necesario. Por regla general, sin embargo, los ESTP consideran innecesario tener que justificar sus acciones, y prefieren, en vez, pasar a la siguiente empresa.
A7: Los ESTP se destacan iniciando empresas en las que logran reunir a grupos distintos para negociar un acuerdo. Son capacitados administradores que saben sacar compañías o instituciones con dificultades económicas rápidamente de su situación de pérdidas, y ¡lo hacen con estilo! Saben vender una idea o proyecto de forma que ningún otro tipo lo logra, pero no se preocuparán de los detalles de dicho proyecto. Esta característica a menudo causa que los ESTP no sean apreciados por el extraordinario talento que tienen puesto que la gente se olvida de la contribución inicial y se concentra en los detalles necesarios para llevar a cabo la idea, llegando incluso a criticar los puntos débiles de los ESTP en lugar de apreciar su aportación. Pocas organizaciones usan a los ESTP como deberían de hacerlo. Sin embargo, cuando los ESTP se encargan de un negocio individualmente, no tendrán éxito en su empresa por sus pocos deseos de cuidarse de los detalles necesarios para que su proyecto salga bien. Los ESTP necesitan que haya alguien que lleve a cabo esos aspectos detallistas de su idea.

Sheet ESTJ
A1: Los ESTJ están muy en contacto con el ambiente externo. Conocen su comunidad y son normalmente los pilares que le dan fuerza. El mejor adjetivo que describe a los ESTJ sería responsables. Representan cerca del 13% de la población general.
A3: Los ESTJ son excelentes para organizar ordenadamente procedimientos y para detallar reglas y reglamentos. Les gusta que las cosas se hagan correctamente. Tienden a impacientarse con aquellos que no siguen los procedimientos con la suficiente atención a los detalles indicados, por los que tienen más experiencia para que el trabajo se lleve a cabo bien.
A5: A los ESTJ les agrada evaluar a otros y tienden a juzgar la actuación de una persona según sigue los procedimientos normales de una operación. A veces serán algo bruscos con los que no siguen correctamente las reglas. Los ESTJ son realistas, prosáicos y más curiosos acerca de nuevos aparatos y procedimientos que acerca de nuevos principios y teorías.
A7: Los ESTJ son generalmente leales a sus instituciones, trabajo y comunidad y se mantendrán siempre fieles a su cónyuge y padres. Saben cuáles son sus responsabilidades y nunca las ignorarán aunque para ello se requieran grandes sacrificios. Alcanzan puestos de alta responsabilidad en su trabajo, en la comunidad y en sus afiliaciones religiosas. A menudo pertenecen a varias organizaciones cívicas y las apoyan con su presencia continua y su actitud expresiva. Los ESTJ son puntuales y esperan lo mismo de otros.
A9: Los ESTJ no reaccionan muy bien a los puntos de vista de otros ni a sus emociones y tienen la tendencia de llegar a conclusiones demasiado rápido. No muestran mucha paciencia para escuchar atentamente ideas opuestas; son especialmente vulnerables a esta tendencia cuando ocupan puestos de autoridad. Necesitarán mantener una mente abierta para apreciar las ideas y reacciones de aquellas personas que dependen de ellos -- sus hijos, su cónyuge y sus empleados.
A11: Los ESTJ se sintonizan de tal modo con las instituciones establecidas y tradicionales con su conducta y actuación que no logran entender que haya gente que desee abandonarlas o cambiarlas radicalmente. Siguen sin dificultades las rutinas del hogar y del trabajo. Les gusta encontrar un sitio para todo y que todo esté en su sitio. Normalmente son pulcros y ordenados tanto en su lugar de empleo como en el de recreo.

Sheet ESFP
A1: Los ESFP irradian calor humano y optimismo. Afables, inteligentes, simpáticos, ingeniosos, volubles y abiertos al medio ambienteÑestos adjetivos describen a los ESTP, quienes, al igual que los ESTP, representan 13 por ciento de la población general. Se divierte uno cuando está con ellos y son los más generosos de todos los tipos. Artista sería la palabra que mejor describe a un ESFP.
A3: Los ESFP evitarán estar solos y buscan la compañía de otros cuando es posible. Los ESFP la encuentran con facilidad porque las otras personas se sienten altamente entretenidas con su presencia. A los ESFP les gusta la diversión y la crean dondequiera que estén. Su goce de la vida es contagioso y siempre se les ve con cara contenta. Les gusta hablar y mostrar su agudeza ingeniosa. Tienen un aire de refinamiento que lo manifiestan en su elegante forma de vestir con ropa de última moda. Saben disfrutar de lo mejor que puede ofrecerles la vida: ropa, comida, confort físico y diversión. Los ESFP crean una sensación de -- come, bebe y disfruta -- por dondequiera que vayan, y alrededor de ellos la vida parece tomar una tonalidad de ambiente festivo y alegre.
A5: El cónyuge de un ESFP tendrá una relación excitante aúnque llena de sorpresas. Para individuos más tranquilos o callados puede crearles algo de ansiedad y tensión al sentirse que viven al borde de una continua aventura. En casa de un ESFP habrá mucha gente que se lo pasa bien. No se permitirá que los problemas "hagan acto de presencia." El ESFP logrará esto tomándose una actitud de que nada desastroso o nefasto ocurrirá ante su presencia.
A7: Los ESFP pueden ser generosos hasta el extremo. Comparten todo lo que tienen sin esperar nada a cambio. Ayudan a todos los que lo necesitan, y quieren abiertamente sin esperar reciprocidad de sentimientos. La vida, según ellos, es una eterna cornucopia de la que manan cantidad de placeres de fácil alcance sin poner mayores esfuerzos para lograrlos.
A9: Dicho talento para gozar de la vida les ocasiona, en muchos casos, caer más en las tentaciones que se les ofrecen que cualquier otro tipo. Al inclinarse a seguir sus impulsos, tanto los ESFP masculinos como femeninos, son vulnerables a cualquier seducción sicológica y física. De ahí que otros puedan sonsacarles lo que quieran con facilidad. Como padres, el ESFP será entretenedor, un amigo y una fuente de diversión y estímulo. Sin embargo, cuando haya alguna enfermedad en la familia, o dificultad, los ESFP puede que se muestren algo impacientes y quieran ausentarse.
A11: Su tolerancia hacia la angustia es la más baja de todos los tipos. La evitan ignorando los aspectos negativos de cualquier situación. Tienden a ser algo autocomplacientes, pero, más que resistir o crear conflictos, los ESFP aparentarán ceder -- y entonces buscar lo que más les interese.

Sheet ESFJ
A1: Los ESFJ, los más sociables de todos los tipos, se sienten más enérgicos cuando se relacionan con la gente. Tienden a idealizar a quienes admiran. La armonía es la clave de este tipo, representado en el 13% de la población general.
A3: Los ESFJ son los grandes tutelares de las instituciones establecidas tales como el hogar, la escuela, la iglesia y los grupos cívicos. Dondequiera que se encuentren, fomentarán la armonía y las relaciones armoniosas. Son excelentes anfitriones que recuerdan el nombre de una persona una vez que son presentados. En una reunión social se les observará atendiendo las necesidades de otros, tratando de asegurarse de que estén a gusto y de que participen en las actividades de la reunión. Los lazos sociales les importan mucho a los ESFJ y su conversación recordará momentos nostálgicos de recuerdos pasados. Los ESFJ desarrollan, apoyan y observan cuidadosamente las tradiciones.
A5: Les duele la indiferencia y necesitan que se les aprecie por lo que son y por la abundancia que ofrecen a otros en la forma de servicios. Tienen muy presentes las apariencias y se toman muy en serio las opiniones de otros en cuanto a las normas sociales se refiere. Los principios de un ESFJ pueden basarse en debería y no debería que expresarán con toda libertad. Son concienzudos y ordenados. Pueden ponerse muy nerviosos cuando se les aisla de la gente.
A7: Para su trabajo los ESFJ se inclinan hacia ocupaciones de servicios. Tienen una personalidad tan abierta que les permite destacarse en ventas y seguramente ganarán premios por ser los representantes que venden más. Suelen tener mayor antigüedad en el departamento de ventas de cualquier organización. Si observamos a un ESFJ cómo trabaja nos revelará cómo este tipo hace su operación personal: el cliente no compra un producto; compra personalmente del ESFJ. Esta misma característica le permite al ESFJ destacarse en la enseñanza, el apostolado, la supervisión, la administración, la dirección técnica de equipos y, en general, puestos en los que trata directamente a las personas. Rara vez causan problemas a sus superiores puesto que obedecen las reglas y los reglamentos y se orientan por el deber y el servicio. Son leales a sus jefes. Los ESFJ atenderán y discutirán los acontecimientos y los problemas de la vida de sus colegas; pero si la conversación trata de abstracciones de filosofía o ciencia, el ESFJ se mostrará inquieto. El análisis de complejidade -- por ejemplo, intentar explicar un evento por el análisis de principios -- no excita el interés del ESFJ, como ocurre en el caso de los NT.
A9: Los consortes ESFJ tienen unos principios que formulan debería y no debería y esperan que su familia los siga. Son muy escrupulosos en cuanto a las responsabilidades en el hogar, ordenados en los asuntos domésticos y prefieren que sus ocupantes sean lo mismo. Disfrutan alternando con la gente y ofreciendo fiestas o pequeñas reuniones con amigos. Los ESFJ quieren que las decisiones familiares se deciden eficiente y rápidamente y que se mantenga un nivel de vida rutinario, ajustándose a un horario que se cumpla religiosamente. No se oponen a ninguna operación rutinaria, respetan los valores tradicionales del hogar, mantienen las promesas del matrimonio y son las personas más comprensivas de todos los tipos. Tienden a depender de sus cónyuges y se casarán para aseguarse un sitio apropiado en su mundo social. Siguen los ritos asociados a cómo servir buena comida y vinos, disfrutan de las ocasiones festivas, estiman y acumulan considerables posesiones materiales. Se toman muy en serio su papel en la comunidad y son sensibles hacia las personas que están en una posición de autoridad con las que se identifican. Tienen muy presente su estado social y a menudo dependen de lo que les dicen personas de influencia para formularse sus propias opiniones y actitudes.

Sheet ENFP
A1: Nada les ocurre a los ENFP que no tenga significado. Demuestran una gran habilidad para descubrir los motivos de otros en sus acciones. De ahí que vean la vida como un drama lleno de posibilidades para el bien y el mal. Aunque este tipo sólo se descubre en el 5% de la gente, su influencia es enorme debido al extraordinario impacto que tienen en otros. Los ENFP se esfuerzan en lograr su autenticidad incluso cuando actúan espontáneamente y dicho esfuerzo lo comunican de modo no verbal a otros, quienes consideran esta cuafidad atractiva. Sin embargo, los ENFP ven que sus propios esfuerzos de lograr autenticidad y espontaneidad son vacíos y, por eso, se "flagelan" por sentirse siempre tan consciences de sí mismos.
A3: Los ENFP consideran muy importantes las experiencias en que sienten intensas emociones. Sin embargo, cuando las tienen, les hacen sentirse incómodos porque sí se dan cuenta de que las experimentan pero notan que una parte de eros se separa. Se esfuerzan por lograr congruencia, pero temen perder contacto con sentimientos reales, que los ENFP poseen en gran variedad e intensidad.
A5: Los ENFP están constantemente observando el mundo que les rodea y nada se les escapa a su atención. Saben concentrarse en la persona que está con ellos y al mismo tiempo apreciar lo que ocurre alrededor. Su atención no es nunca superficial ni pasiva; constantemente directa. A veces, los ENFP se encuentran interpretando situaciones en términos de los ''motivos posteriores" de la otra persona, dándoles un significado especial a sus palabras o acciones. En muchos casos dicha interpretación resulta ser negativa e incluso falsa. En el proceso, un ENFP puede encontrar que ha introducido elementos innecesarios y tóxicos en la relación. Aunque los ENFP son extremadamente perceptivos, cometen serios errores de juicio que les causa una sensación angustiosa. Estos errores se derivan de una tendencia a analizar las circunstancias a través de sus propios prejuicios personales. Sus percepciones pueden ser correctas pero sus conclusiones no.
A7: Como viven en un estado de alerta continuo y son extremadamente sensibles, sufren a menudo de gran tensión muscular. Viven preparados para las emergencies. Y como ellos son asi, creen que el resto ha de actuar igual. Se aburren con frecuencia de situaciones y personas y evitan repetir una experiencia. Disfrutan cuando crean algo nuevo -- una idea o un proyecto, pero no les interesa llevarlo a cabo. Su entusiasmo es contagioso y la gente queda cautivada por el carácter de un ENFP. Y a la vez son extremadamente independientes, rechazando cualquier tipo de subordinación que alguien trate de imponerles a ellos o a cualquier persona relacionada a ellos. Sin embargo, tienden a atribuir más poder a aquellas figuras autoritarias del que tienen y conceder a dichos individuos la habilidad de ver más allá de lo que un ENFP es de hecho. Mientras que los ENFP resisten la idea de que otros dependan de ellos o de que tengan poder sobre ellos, su carisma atrae a individuos que buscan que se les ensefie el camino. Los ENFP se hallan constantemente rodeados de gente que espera encontrar consejo, inspiración, dirección, empuje, etc.-- una circunstancia que, en muchos casos, le crea una sensación de peso y fastidio.

Sheet ENFJ
A1: Los ENFJ son excelentes líderes de grupo, tanto de trabajo como de desarrollo social o personal. Poseen la atractiva característica de saber que sus ideas o sugerencias serán fácilmente aceptadas, sin dudar ni un momento que la gente hará lo que ellos sugieran. Y, por lo general, así ocurre puesto que este tipo demuestra un extraordinario don de gentes. Los ENFJ dan gran valor a la cooperación de otros a la vez que ellos condescienden bien a cooperar.
